5.	What will be the output of the below code. Provide necessary information to support your decision.

#include <iostream>
class Printer {
public:
Printer() {}
    ~ Printer() {
        throw 42}
};
int main(int argc, const char * argv[]) {
    try {
Printer hp;
        throw 32;
    } catch(int a) {
        std::cout << a;
    }
}

Output: Runtime Error
Explanation: In this program calling the destructors for automatic objects from a try block to a throw-expression.
In the exception is not caught. 
